package com.sksamuel.kotest.timeout

import io.kotest.core.spec.style.FunSpec
import io.kotest.core.test.TestResult
import io.kotest.matchers.shouldBe
import kotlinx.coroutines.delay
import kotlin.time.ExperimentalTime
import kotlin.time.milliseconds

// tests that the values in the timeout exception are populated correctly
@OptIn(ExperimentalTime::class)
class SpecInvocationTimeoutExceptionTest : FunSpec() {
   init {

      timeout = 897
      invocationTimeout = 10 // millis

      test("timeout exception should use the value that caused the test to fail") {
         delay(100.milliseconds)
      }

      aroundTest { (test, execute) ->
         val result = execute(test)
         result.error?.message shouldBe "Test did not complete within 10ms"
         TestResult.success(0)
      }
   }
}

// tests that the values in the timeout exception are populated correctly
@OptIn(ExperimentalTime::class)
class TestInvocationTimeoutExceptionTest : FunSpec() {
   init {

      timeout = 965
      invocationTimeout = 100 // millis

      test("timeout exception should use the value that caused the test to fail 1").config(invocationTimeout = 12.milliseconds) {
         delay(100.milliseconds)
      }

      test("timeout exception should use the value that caused the test to fail 2").config(
         timeout = 24.milliseconds,
         invocationTimeout = 12.milliseconds
      ) {
         delay(100.milliseconds)
      }

      aroundTest { (test, execute) ->
         val result = execute(test)
         result.error?.message shouldBe "Test did not complete within 12ms"
         TestResult.success(0)
      }
   }
}


// tests that the values in the timeout exception are populated correctly
@OptIn(ExperimentalTime::class)
class SpecTimeoutExceptionTest : FunSpec() {
   init {

      timeout = 21

      test("timeout exception should use the value that caused the test to fail") {
         delay(100.milliseconds)
      }

      aroundTest { (test, execute) ->
         val result = execute(test)
         result.error?.message shouldBe "Test did not complete within 21ms"
         TestResult.success(0)
      }
   }
}


// tests that the values in the timeout exception are populated correctly
@OptIn(ExperimentalTime::class)
class TestTimeoutExceptionTest : FunSpec() {
   init {

      timeout = 250

      test("timeout exception should use the value that caused the test to fail").config(timeout = 23.milliseconds) {
         delay(100.milliseconds)
      }

      aroundTest { (test, execute) ->
         val result = execute(test)
         result.error?.message shouldBe "Test did not complete within 23ms"
         TestResult.success(0)
      }
   }
}
